Workbook
Name CASE: '[1]Operating Model'!#REF!
Name CIRC: '[1]Operating Model'!#REF!
Name PIK: [2]LBO!$E$8
Name tgr: Empty!$D$10
Name tgr: WACC!#REF!
Name tgr: #REF!
Name wacc: Empty!$D$9
Name wacc: WACC!#REF!
Name wacc: #REF!

Sheet __FDSCACHE__
B1: This sheet contains FactSet XML data for use with this workbook's =FDS codes. Modifying the worksheet's contents may damage the workbook's =FDS functionality.

Sheet Empty
B2: Amazon DCF
A4: x | B4: Ticker | C4: ROSN.ME | E4: Implied Share Price
B5: Date | C5: 44766 | E5: Today's Share Price | I5: Upside (Downside)
A7: x | B7: Assumptions
B8: Valuation Assumptions
B9: WACC | D9: =WACC!D22 -> 0.078205784 | I9: PROJECTIONS
B10: TGR | D10: 0.03
I11: 1 | J11: 2 | K11: 3 | L11: 4 | M11: 5 | N11: 6
A12: x | B12: Income Statement | E12: 2022 | F12: 2023 | G12: 2024 | H12: 2025 | I12: 2026 | J12: 2027 | K12: 2028 | L12: 2029 | M12: 2030 | N12: 2031
B13: Revenue | E13: =IS!K5 -> 9000 | F13: =IS!L5 -> 8990 | G13: =IS!M5 -> 9972 | H13: =IS!N5 -> 8164 | I13: =IS!J5 -> - | J13: =IS!K5 -> 9000 | K13: =IS!L5 -> 8990 | L13: =IS!M5 -> 9972 | M13: =IS!N5 -> 8164 | N13: =IS!O5 -> -
B14: % growth | F14: =F13/E13-1 -> -0.0011111111 | G14: =G13/F13-1 -> 0.10923248 | H14: =H13/G13-1 -> -0.18130766 | I14: =I13/H13-1 -> #VALUE! | J14: =J13/I13-1 -> #VALUE! | K14: =K13/J13-1 -> -0.0011111111 | L14: =L13/K13-1 -> 0.10923248 | M14: =M13/L13-1 -> -0.18130766 | N14: =N13/M13-1 -> #VALUE!
B16: EBIT | E16: =IS!K15-IS!K18 -> #VALUE! | F16: =IS!L15-IS!L18 -> 2236 | G16: =IS!M15-IS!M18 -> 2180 | H16: =IS!N15-IS!N18 -> 1204 | I16: =IS!O15-IS!O18 -> #VALUE! | J16: =IS!K19 -> - | K16: =IS!L19 -> 2189 | L16: =IS!M19 -> 2129 | M16: =IS!N19 -> 1087 | N16: =IS!O19 -> -
B17: % of sales | E17: =E16/E13 -> #VALUE! | F17: =F16/F13 -> 0.2487208 | G17: =G16/G13 -> 0.21861211 | H17: =H16/H13 -> 0.14747673 | I17: =I16/I13 -> #VALUE! | J17: =J16/J13 -> #VALUE! | K17: =K16/K13 -> 0.24349277 | L17: =L16/L13 -> 0.21349779 | ... N17: =N16/N13 -> #VALUE!
B19: Taxes | E19: =IS!F27 -> - | F19: =IS!L27 -> -438 | G19: =IS!M27 -> -552 | H19: =IS!N27 -> -275 | I19: =IS!O27 -> - | J19: =IS!K27 -> - | K19: =IS!L27 -> -438 | L19: =IS!M27 -> -552 | M19: =IS!N27 -> -275 | N19: =IS!O27 -> -
B20: % of EBIT | E20: =E19/E16 -> #VALUE! | F20: =F19/F16 -> -0.19588551 | G20: =G19/G16 -> -0.25321101 | H20: =H19/H16 -> -0.22840532 | I20: =I19/I16 -> #VALUE! | J20: =J19/J16 -> #VALUE! | K20: =K19/K16 -> -0.20009137 | L20: =L19/L16 -> -0.25927666 | ... N20: =N19/N16 -> #VALUE!
A22: x | B22: Cash Flow Items | E22: 2022 | F22: 2023 | G22: 2024 | H22: 2025 | I22: 2026 | J22: 2028 | K22: 2029 | L22: 2030 | M22: 2031 | N22: 2032
B23: D&A | E23: =IS!K18 -> - | F23: =IS!L18 -> 769 | G23: =IS!M18 -> 849 | H23: =IS!N18 -> 969 | I23: =IS!O18 -> - | J23: 38716.438 | K23: 44728.72 | L23: 52136.97 | M23: 55507.54 | N23: 58234.55
B24: % of sales | E24: =E23/E13 -> #VALUE! | F24: =F23/F13 -> 0.085539488 | G24: =G23/G13 -> 0.085138387 | H24: =H23/H13 -> 0.11869182 | I24: =I23/I13 -> #VALUE! | J24: =J23/J13 -> 4.3018264 | K24: =K23/K13 -> 4.975386 | L24: =L23/L13 -> 5.2283363 | ... N24: =N23/N13 -> #VALUE!
B26: CapEx | E26: =IS!K11 -> 1132 | F26: =IS!L11 -> 1297 | G26: =IS!M11 -> 1442 | H26: =IS!N11 -> 1360 | I26: =IS!O11 -> - | J26: 61050.723 | K26: 62598.887 | L26: 64481.453 | M26: 69493.41 | N26: 65697
B27: % of sales | E27: =E26/E13 -> 0.12577778 | F27: =F26/F13 -> 0.14427141 | G27: =G26/G13 -> 0.14460489 | H27: =H26/H13 -> 0.16658501 | I27: =I26/I13 -> #VALUE! | J27: =J26/J13 -> 6.7834137 | K27: =K26/K13 -> 6.9631687 | L27: =L26/L13 -> 6.4662508 | ... N27: =N26/N13 -> #VALUE!
B29: Change in NWC | F29: =(CFS!D9-CFS!D12)-(CFS!C9-CFS!C12) -> -708 | G29: =(CFS!E9-CFS!E12)-(CFS!D9-CFS!D12) -> -1901 | H29: =(CFS!F9-CFS!F12)-(CFS!E9-CFS!E12) -> -323 | I29: =(CFS!G9-CFS!G12)-(CFS!F9-CFS!F12) -> 3925
B30: % of sales | E30: =E29/E13 -> 0 | F30: =F29/F13 -> -0.078754171 | G30: =G29/G13 -> -0.19063377 | H30: =H29/H13 -> -0.039563939 | I30: =I29/I13 -> #VALUE!
I31: 1 | J31: 2 | K31: 3 | L31: 4 | M31: 5 | N31: 6
A32: x | B32: DCF | E32: =E22 -> 2022 | F32: =F22 -> 2023 | G32: =G22 -> 2024 | H32: =H22 -> 2025 | I32: =I22 -> 2026 | J32: =J22 -> 2028 | K32: =K22 -> 2029 | L32: =L22 -> 2030 | ... N32: =N22 -> 2032
B33: Revenue | E33: =E13 -> 9000 | F33: =F13 -> 8990 | G33: =G13 -> 9972 | H33: =H13 -> 8164 | I33: =I13 -> - | J33: =I33*(1+J34) -> #VALUE! | K33: =J33*(1+K34) -> #VALUE! | L33: =K33*(1+L34) -> #VALUE! | M33: =L33*(1+M34) -> #VALUE! | N33: =M33*(1+N34) -> #VALUE!
B34: % growth | F34: =F33/E33-1 -> -0.0011111111 | G34: =G33/F33-1 -> 0.10923248 | H34: =H33/G33-1 -> -0.18130766 | I34: =I33/H33-1 -> #VALUE! | J34: =J14 -> #VALUE! | K34: =K14 -> -0.0011111111 | L34: =L14 -> 0.10923248 | M34: =M14 -> -0.18130766 | N34: =N14 -> #VALUE!
B36: EBIT | E36: =E16 -> #VALUE! | F36: =F16 -> 2236 | G36: =G16 -> 2180 | H36: =H16 -> 1204 | I36: =I16 -> #VALUE! | J36: =J33*(J37) -> #VALUE! | K36: =K33*(K37) -> #VALUE! | L36: =L33*(L37) -> #VALUE! | M36: =M33*(M37) -> #VALUE! | N36: =N33*(N37) -> #VALUE!
B37: % margin | E37: =E36/E33 -> #VALUE! | F37: =F36/F33 -> 0.2487208 | G37: =G36/G33 -> 0.21861211 | H37: =H36/H33 -> 0.14747673 | I37: =I36/I33 -> #VALUE! | J37: =J17 -> #VALUE! | K37: =K17 -> 0.24349277 | L37: =L17 -> 0.21349779 | M37: =M17 -> 0.13314552 | N37: =N17 -> #VALUE! | P37: THE %MARGIN is the difference of the Revenue and the final EBIT
B39: Taxes | E39: =IS!K27 -> - | F39: =IS!L27 -> -438 | G39: =IS!M27 -> -552 | H39: =IS!N27 -> -275 | I39: =IS!O27 -> - | J39: =J40*J36 -> #VALUE! | K39: =K40*K36 -> #VALUE! | L39: =L40*L36 -> #VALUE! | M39: =M40*M36 -> #VALUE! | N39: =N40*N36 -> #VALUE!
B40: % of EBIT | E40: =E39/E36 -> #VALUE! | F40: =F39/F36 -> -0.19588551 | G40: =G39/G36 -> -0.25321101 | H40: =H39/H36 -> -0.22840532 | I40: =I39/I36 -> #VALUE! | J40: =J20 -> #VALUE! | K40: =K20 -> -0.20009137 | L40: =L20 -> -0.25927666 | M40: =M20 -> -0.25298988 | N40: =N20 -> #VALUE!
B42: EBIAT | J42: =J36-J39 -> #VALUE! | K42: =K36-K39 -> #VALUE! | L42: =L36-L39 -> #VALUE! | M42: =M36-M39 -> #VALUE! | N42: =N36-N39 -> #VALUE!
B44: D&A | J44: =J23 -> 38716.438 | K44: =K23 -> 44728.72 | L44: =L23 -> 52136.97 | M44: =M23 -> 55507.54 | N44: =N23 -> 58234.55
B45: % of sales | J45: =J44/J33 -> #VALUE! | K45: =K44/K33 -> #VALUE! | L45: =L44/L33 -> #VALUE! | M45: =M44/M33 -> #VALUE! | N45: =N44/N33 -> #VALUE!
B47: CapEx | J47: =J26 -> 61050.723 | K47: =K26 -> 62598.887 | L47: =L26 -> 64481.453 | M47: =M26 -> 69493.41 | N47: =N26 -> 65697
B48: % of sales | J48: =J47/J33 -> #VALUE! | K48: =K47/K33 -> #VALUE! | L48: =L47/L33 -> #VALUE! | M48: =M47/M33 -> #VALUE! | N48: =N47/N33 -> #VALUE!
B50: Change in NWC | J50: =J51*J33 -> #VALUE! | K50: =K51*K33 -> #VALUE! | L50: =L51*L33 -> #VALUE! | M50: =M51*M33 -> #VALUE! | N50: =N51*N33 -> #VALUE!
B51: % of sales | J51: =AVERAGE(G30:I30) -> #VALUE! | K51: =J51 -> #VALUE! | L51: =K51 -> #VALUE! | M51: =L51 -> #VALUE! | N51: =M51 -> #VALUE!
B53: Unlevered FCF | J53: =J42+J44-J47-J50 -> #VALUE! | K53: =K42+K44-K47-K50 -> #VALUE! | L53: =L42+L44-L47-L50 -> #VALUE! | M53: =M42+M44-M47-M50 -> #VALUE! | N53: =N42+N44-N47-N50 -> #VALUE!
B54: Present Value of FCF | J54: =J53/(1+wacc)^J31 -> #VALUE! | K54: =K53/(1+wacc)^K31 -> #VALUE! | L54: =L53/(1+wacc)^L31 -> #VALUE! | M54: =M53/(1+wacc)^M31 -> #VALUE! | N54: =N53/(1+wacc)^N31 -> #VALUE!
A56: x | B56: Terminal Value | N56: =(N53*(1+tgr))/(wacc-tgr) -> #VALUE!
...

Sheet IS
A1: ROSNEFT-RU
A2: Income Statement (M)
B3: CY '13 | C3: CY '14 | D3: CY '15 | E3: CY '16 | F3: CY '17 | G3: CY '18 | H3: CY '19 | I3: CY '20 | J3: CY '21 | K3: CY '22 | L3: CY '23 | M3: CY '24 | N3: CY '25 | O3: CY '26 | P3: CY '27
B4: Dec '13 | C4: Dec '14 | D4: Dec '15 | E4: Dec '16 | F4: Dec '17 | G4: Dec '18 | H4: Dec '19 | I4: Dec '20 | J4: Dec '21 | K4: Dec '22 | L4: Dec '23 | M4: Dec '24 | N4: Dec '25 | O4: Dec '26 | P4: Dec '27
A5: Sales | B5: - | C5: - | D5: - | E5: - | F5: - | G5: - | H5: - | I5: - | J5: - | K5: 9000 | L5: 8990 | M5: 9972 | N5: 8164 | O5: - | P5: -
A6: Cost of Sales | B6: - | C6: - | D6: - | E6: - | F6: - | G6: - | H6: - | I6: - | J6: - | K6: - | L6: - | M6: - | N6: - | O6: - | P6: -
A7: Organic Growth (%) | B7: - | C7: - | D7: - | E7: - | F7: - | G7: - | H7: - | I7: - | J7: - | K7: - | L7: - | M7: - | N7: - | O7: - | P7: -
A8: Constant Currency Revenue Growth (%) | B8: - | C8: - | D8: - | E8: - | F8: - | G8: - | H8: - | I8: - | J8: - | K8: - | L8: - | M8: - | N8: - | O8: - | P8: -
A9: Gross Income | B9: - | C9: - | D9: - | E9: - | F9: - | G9: - | H9: - | I9: - | J9: - | K9: - | L9: - | M9: - | N9: - | O9: - | P9: -
A10: SG&A Expense | B10: - | C10: - | D10: - | E10: - | F10: - | G10: - | H10: - | I10: - | J10: - | K10: - | L10: - | M10: - | N10: - | O10: - | P10: -
A11: CAPEX | B11: - | C11: - | D11: - | E11: - | F11: - | G11: - | H11: - | I11: - | J11: - | K11: 1132 | L11: 1297 | M11: 1442 | N11: 1360 | O11: - | P11: -
A12: General & Admin Expense | B12: - | C12: - | D12: - | E12: - | F12: - | G12: - | H12: - | I12: - | J12: - | K12: - | L12: - | M12: - | N12: - | O12: - | P12: -
A13: Research & Development | B13: - | C13: - | D13: - | E13: - | F13: - | G13: - | H13: - | I13: - | J13: - | K13: - | L13: - | M13: - | N13: - | O13: - | P13: -
A14: EBITDAR | B14: - | C14: - | D14: - | E14: - | F14: - | G14: - | H14: - | I14: - | J14: - | K14: - | L14: - | M14: - | N14: - | O14: - | P14: -
A15: EBITDA | B15: - | C15: - | D15: - | E15: - | F15: - | G15: - | H15: - | I15: - | J15: - | K15: 2551 | L15: 3005 | M15: 3029 | N15: 2173 | O15: - | P15: -
A16: EBITDA Non-GAAP | B16: - | C16: - | D16: - | E16: - | F16: - | G16: - | H16: - | I16: - | J16: - | K16: - | L16: - | M16: - | N16: - | O16: - | P16: -
A17: EBITDA GAAP | B17: - | C17: - | D17: - | E17: - | F17: - | G17: - | H17: - | I17: - | J17: - | K17: - | L17: - | M17: - | N17: - | O17: - | P17: -
A18: Depr. & Amort. | B18: - | C18: - | D18: - | E18: - | F18: - | G18: - | H18: - | I18: - | J18: - | K18: - | L18: 769 | M18: 849 | N18: 969 | O18: - | P18: -
A19: Operating Income | B19: - | C19: - | D19: - | E19: - | F19: - | G19: - | H19: - | I19: - | J19: - | K19: - | L19: 2189 | M19: 2129 | N19: 1087 | O19: - | P19: -
A20: EBITA | B20: - | C20: - | D20: - | E20: - | F20: - | G20: - | H20: - | I20: - | J20: - | K20: - | M20: - | N20: - | O20: -
A21: Operating Income - Non GAAP | B21: - | C21: - | D21: - | E21: - | F21: - | G21: - | H21: - | I21: - | J21: - | K21: - | L21: 2129 | M21: 2180 | N21: 1087 | O21: - | P21: -
A22: Operating Income - GAAP | B22: - | C22: - | D22: - | E22: - | F22: - | G22: - | H22: - | I22: - | J22: - | K22: - | L22: 2129 | M22: 2180 | N22: - | O22: - | P22: -
A23: Interest Expense | B23: - | C23: - | D23: - | E23: - | F23: - | G23: - | H23: - | I23: - | J23: - | K23: - | L23: - | M23: - | N23: - | O23: - | P23: -
A24: Pretax Income | B24: - | C24: - | D24: - | E24: - | F24: - | G24: - | H24: - | I24: - | J24: - | K24: - | L24: 1957 | M24: 1893 | N24: 819 | O24: - | P24: -
A25: Pretax Income - Non GAAP | B25: - | C25: - | D25: - | E25: - | F25: - | G25: - | H25: - | I25: - | J25: - | K25: - | L25: - | M25: - | N25: - | O25: - | P25: -
A26: Pretax Income - GAAP | B26: - | C26: - | D26: - | E26: - | F26: - | G26: - | H26: - | I26: - | J26: - | K26: - | L26: 1957 | M26: 1893 | N26: 819 | O26: - | P26: -
A27: Tax Expense | B27: - | C27: - | D27: - | E27: - | F27: - | G27: - | H27: - | I27: - | J27: - | K27: - | L27: -438 | M27: -552 | N27: -275 | O27: - | P27: -
A28: Net Income | B28: - | C28: - | D28: - | E28: - | F28: - | G28: - | H28: - | I28: - | J28: - | K28: 813 | L28: 1529 | M28: 1341 | N28: 544 | O28: - | P28: -
A29: Net Income - Non GAAP | B29: - | C29: - | D29: - | E29: - | F29: - | G29: - | H29: - | I29: - | J29: - | K29: - | L29: 1529 | M29: 1341 | N29: - | O29: - | P29: -
A30: Net Income - GAAP | B30: - | C30: - | D30: - | E30: - | F30: - | G30: - | H30: - | I30: - | J30: - | K30: - | L30: 1529 | M30: 1341 | N30: - | O30: - | P30: - | Q30: -
A31: METRICS | B31: - | C31: - | D31: - | E31: - | F31: - | G31: - | H31: - | I31: - | J31: - | K31: - | M31: - | N31: - | O31: - | P31: -
A32: EBITDA Margin | B32: - | C32: - | D32: - | E32: - | F32: - | G32: - | H32: - | I32: - | J32: - | K32: - | L32: =L15/L5 -> 0.33426029 | M32: =M15/M5 -> 0.3037505 | N32: =N15/N5 -> 0.26616854 | O32: - | P32: -
A33: Operating Margin | B33: - | C33: - | D33: - | E33: - | F33: - | G33: - | H33: - | I33: - | J33: - | K33: - | L33: =L21/L5 -> 0.23681869 | M33: =M21/M5 -> 0.21861211 | N33: =N21/N5 -> 0.13314552 | O33: - | P33: -
A34: Net income margin | B34: - | C34: - | D34: - | E34: - | F34: - | G34: - | H34: - | I34: - | J34: - | K34: - | L34: =L28/L5 -> 0.17007786 | M34: =M28/M5 -> 0.13447653 | N34: =N28/N5 -> 0.066634003 | O34: - | P34: -
A35: CAPEX/EBITDA | B35: - | C35: - | D35: - | E35: - | F35: - | G35: - | H35: - | I35: - | J35: - | K35: - | L35: - | M35: - | N35: - | O35: - | P35: -
A36: FCF/EBITDA | B36: - | C36: - | D36: - | E36: - | F36: - | G36: - | H36: - | I36: - | J36: - | K36: - | L36: - | M36: - | N36: - | O36: - | P36: -
A37: Effective Tax Rate | B37: - | C37: - | D37: - | E37: - | F37: - | G37: - | H37: - | I37: - | J37: - | K37: - | L37: =L27/L26 -> -0.22381196 | M37: =M27/M26 -> -0.29160063 | N37: =N27/N26 -> -0.33577534 | O37: - | P37: -
A38: Cash Conversion | B38: - | C38: - | D38: - | E38: - | F38: - | G38: - | H38: - | I38: - | J38: - | K38: - | L38: - | M38: - | N38: - | O38: - | P38: -
A39: D&A Revenue | B39: - | C39: - | D39: - | E39: - | F39: - | G39: - | H39: - | I39: - | J39: - | K39: - | L39: =L18/L5 -> 0.085539488 | M39: =M18/M5 -> 0.085138387 | N39: =N18/N5 -> 0.11869182 | O39: - | P39: -

Sheet WACC
B2: WACC
A4: x | B4: WACC
B5: WACC = (% Equity x Cost of Equity) + (% Debt x Cost of Debt x (1 -Tax rate))
B6: Cost of Equity = Risk Free Rate + (Beta x (Expected Market Return - Risk Free Rate))
B8: Debt | D8: =Empty!N60 -> 47556
B9: % Debt | D9: =D8/D20 -> 0.036650441
B10: Cost of Debt | D10: 0.02
B11: Tax Rate | D11: 0.21
B13: Equity Value | D13: 1250000
B14: % Equity | D14: =D13/D20 -> 0.96334956
B15: Cost of Equity | D15: =D16+D17*D18 -> 0.08058
B16: Risk Free Rate | D16: 0.02758
B17: Beta | D17: 1.25
B18: Market Risk Premium | D18: 0.0424
B20: Debt + Equity | D20: =D8+D13 -> 1297556
A22: x | B22: WACC | D22: =(D9*D10*(1-D11))+(D14*D15) -> 0.078205784

Sheet CFS
A4: Rosneft Oil Company
A5: ROSN Currency: RUB Unit: millions
A6: Source: Summary Consolidated Financial Statements (IFRS)
A8: Line Item | B8: 2022 | C8: 2023 | D8: 2024 | E8: 2025 | F8: 2026 H1
A9: Current assets | B9: n/a | C9: 3839 | D9: 4283 | E9: 4199 | F9: 4004
A10: Total non-current assets | B10: n/a | C10: 14948 | D10: 16399 | E10: 17361 | F10: 17652
A11: Total assets | B11: n/a | C11: 18787 | D11: 20682 | E11: 21560 | F11: 21656
A12: Current liabilities | B12: n/a | C12: 4832 | D12: 5984 | E12: 7801 | F12: 7929
A13: Non-current liabilities | B13: n/a | C13: 5541 | D13: 5541 | E13: 4681 | F13: 442
A14: Total equity | B14: n/a | C14: 8414 | D14: 9157 | E14: 9078 | F14: 9285
A15: Total revenues and equity share in profits | B15: 9163 | C15: 9163 | D15: 10139 | E15: 8236 | F15: 4289
A16: Production and operating expenses | B16: 675 | C16: 675 | D16: 895 | E16: 1109 | F16: 419
A17: Depreciation, depletion, amortization and impairment | B17: 769 | C17: 769 | D17: 848 | E17: 969 | F17: 663
A18: Taxes other than income tax | B18: 3156 | C18: 3156 | D18: 3639 | E18: 2771 | F18: 1451
A19: Other costs and expenses | B19: 2381 | C19: 2381 | D19: 2628 | E19: 2300 | F19: 1115
A20: Total costs and expenses | B20: 6981 | C20: 6981 | D20: 8010 | E20: 7149 | F20: 3648
A21: Operating profit | B21: 2182 | C21: 2182 | D21: 2129 | E21: 1087 | F21: 641
A22: Profit before income tax | B22: 1957 | C22: 1957 | D22: 1893 | E22: 819 | F22: 446
A23: Income tax expense | B23: -438 | C23: -428 | D23: -552 | E23: -275 | F23: -164
A24: Profit for the year | B24: 1529 | C24: 1529 | D24: 1341 | E24: 544 | F24: 282
A25: Profit for the year attributable to Rosneft shareholders | B25: 1267 | C25: 1267 | D25: 1084 | E25: 293 | F25: 200
A26: Net cash provided by operating activities | B26: 2765 | C26: 2765 | D26: 2465 | E26: n/a | F26: n/a
A27: Net cash used in investing activities | B27: -1193 | C27: -1537 | D27: -1429 | E27: n/a | F27: n/a
A28: Net cash used in financing activities | B28: -1537 | C28: -1537 | D28: -706 | E28: n/a | F28: n/a
A29: Capital expenditures | B29: -1297 | C29: -1297 | D29: -1442 | E29: n/a | F29: n/a
A30: Net increase in cash and cash equivalents | B30: 35 | C30: 35 | D30: 330 | E30: n/a | F30: n/a
